Traceback (most recent call last):
  File "/home/labra/src/python/rudof/tutorials/.venv/lib/python3.12/site-packages/jupyter_core/utils/__init__.py", line 154, in wrapped
    asyncio.get_running_loop()
RuntimeError: no running event loop

During handling of the above exception, another exception occurred:

Traceback (most recent call last):
  File "/home/labra/src/python/rudof/tutorials/.venv/lib/python3.12/site-packages/jupyter_cache/executors/utils.py", line 58, in single_nb_execution
    executenb(
  File "/home/labra/src/python/rudof/tutorials/.venv/lib/python3.12/site-packages/nbclient/client.py", line 1319, in execute
    return NotebookClient(nb=nb, resources=resources, km=km, **kwargs).execute()
           ^^^^^^^^^^^^^^^^^^^^^^^^^^^^^^^^^^^^^^^^^^^^^^^^^^^^^^^^^^^^^^^^^^^^^
  File "/home/labra/src/python/rudof/tutorials/.venv/lib/python3.12/site-packages/jupyter_core/utils/__init__.py", line 158, in wrapped
    return loop.run_until_complete(inner)
           ^^^^^^^^^^^^^^^^^^^^^^^^^^^^^^
  File "/usr/lib/python3.12/asyncio/base_events.py", line 687, in run_until_complete
    return future.result()
           ^^^^^^^^^^^^^^^
  File "/home/labra/src/python/rudof/tutorials/.venv/lib/python3.12/site-packages/nbclient/client.py", line 709, in async_execute
    await self.async_execute_cell(
  File "/home/labra/src/python/rudof/tutorials/.venv/lib/python3.12/site-packages/nbclient/client.py", line 1062, in async_execute_cell
    await self._check_raise_for_error(cell, cell_index, exec_reply)
  File "/home/labra/src/python/rudof/tutorials/.venv/lib/python3.12/site-packages/nbclient/client.py", line 918, in _check_raise_for_error
    raise CellExecutionError.from_cell_and_msg(cell, exec_reply_content)
nbclient.exceptions.CellExecutionError: An error occurred while executing the following cell:
------------------
query = """prefix : <http://example.org/>
select ? where {
  ?x a :Person
}
"""

results = rudof.run_query_str(query)

------------------

----- stdout -----
RudofError: Error running query prefix : <http://example.org/>
select ? where {
  ?x a :Person
}
: error at 2:16: expected DISTINCT
From<RudofError>: Error running query prefix : <http://example.org/>
select ? where {
  ?x a :Person
}
: error at 2:16: expected DISTINCT
------------------

[31m---------------------------------------------------------------------------[39m
[31mValueError[39m                                Traceback (most recent call last)
[36mCell[39m[36m [39m[32mIn[10][39m[32m, line 7[39m
[32m      1[39m query = [33m"""[39m[33mprefix : <http://example.org/>[39m
[32m      2[39m [33mselect ? where [39m[33m{[39m
[32m      3[39m [33m  ?x a :Person[39m
[32m      4[39m [33m}[39m
[32m      5[39m [33m"""[39m
[32m----> [39m[32m7[39m results = [43mrudof[49m[43m.[49m[43mrun_query_str[49m[43m([49m[43mquery[49m[43m)[49m

[31mValueError[39m: Error running query prefix : <http://example.org/>
select ? where {
  ?x a :Person
}
: error at 2:16: expected DISTINCT

